<?xml version="1.0"?>
<robot name="sphere_pusher">
    <!-- Dummy Link for Base -->
    <link name="base_link_dummy">
        <visual>
            <geometry>
                <sphere radius="0.01"/> <!-- Slightly larger size -->
            </geometry>
        </visual>
        <collision>
            <geometry>
                <sphere radius="0.01"/>
            </geometry>
        </collision>
        <inertial>
            <mass value="0.01"/> <!-- Low mass but not negligible -->
            <inertia ixx="0.01" ixy="0" ixz="0" iyy="0.01" iyz="0" izz="0.01"/> <!-- Proportional inertia -->
        </inertial>
    </link>

    <!-- Base Link without Inertia -->
    <link name="base_link">
        <visual>
            <geometry>
                <box size="0.5 0.3 0.1"/>
            </geometry>
            <material name="blue">
                <color rgba="0 0 1 1"/>
            </material>
        </visual>
        <collision>
            <geometry>
                <box size="0.5 0.3 0.1"/>
            </geometry>
        </collision>
    </link>

    <!-- Fixed Joint connecting base_link to base_link_dummy -->
    <joint name="base_to_dummy" type="fixed">
        <parent link="base_link"/>
        <child link="base_link_dummy"/>
    </joint>

    <!-- Left Wheel -->
    <link name="left_wheel">
        <visual>
            <geometry>
                <cylinder radius="0.05" length="0.05"/>
            </geometry>
            <origin rpy="1.5708 0 0" xyz="0 0 0"/>
            <material name="black">
                <color rgba="0 0 0 1"/>
            </material>
        </visual>
        <collision>
            <geometry>
                <cylinder radius="0.05" length="0.05"/>
            </geometry>
            <origin rpy="1.5708 0 0" xyz="0 0 0"/>
        </collision>
        <inertial>
            <mass value="0.5"/>
            <inertia ixx="0.01" ixy="0" ixz="0" iyy="0.01" iyz="0" izz="0.01"/>
            <origin xyz="0 0 0" rpy="0 0 0"/>
        </inertial>
    </link>

    <joint name="left_wheel_joint" type="revolute">
        <parent link="base_link"/>
        <child link="left_wheel"/>
        <origin xyz="-0.2 0.176 -0.04" rpy="0 0 0"/>
        <axis xyz="0 1 0"/>
        <limit lower="0" upper="6.2832" effort="100" velocity="10"/>
    </joint>

    <!-- Transmission for Left Wheel -->
    <transmission name="left_wheel_transmission">
        <type>transmission_interface/SimpleTransmission</type>
        <joint name="left_wheel_joint">
            <hardwareInterface>hardware_interface/VelocityJointInterface</hardwareInterface>
        </joint>
        <actuator name="left_wheel_motor">
            <hardwareInterface>hardware_interface/VelocityJointInterface</hardwareInterface>
            <mechanicalReduction>1.0</mechanicalReduction>
        </actuator>
    </transmission>

    <!-- Right Wheel -->
    <link name="right_wheel">
        <visual>
            <geometry>
                <cylinder radius="0.05" length="0.05"/>
            </geometry>
            <origin rpy="1.5708 0 0" xyz="0 0 0"/>
            <material name="black">
                <color rgba="0 0 0 1"/>
            </material>
        </visual>
        <collision>
            <geometry>
                <cylinder radius="0.05" length="0.05"/>
            </geometry>
            <origin rpy="1.5708 0 0" xyz="0 0 0"/>
        </collision>
        <inertial>
            <mass value="0.5"/>
            <inertia ixx="0.01" ixy="0" ixz="0" iyy="0.01" iyz="0" izz="0.01"/>
            <origin xyz="0 0 0" rpy="0 0 0"/>
        </inertial>
    </link>

    <joint name="right_wheel_joint" type="revolute">
        <parent link="base_link"/>
        <child link="right_wheel"/>
        <origin xyz="-0.2 -0.176 -0.04" rpy="0 0 0"/>
        <axis xyz="0 1 0"/>
        <limit lower="0" upper="6.2832" effort="100" velocity="10"/>
    </joint>

    <!-- Transmission for Right Wheel -->
    <transmission name="right_wheel_transmission">
        <type>transmission_interface/SimpleTransmission</type>
        <joint name="right_wheel_joint">
            <hardwareInterface>hardware_interface/VelocityJointInterface</hardwareInterface>
        </joint>
        <actuator name="right_wheel_motor">
            <hardwareInterface>hardware_interface/VelocityJointInterface</hardwareInterface>
            <mechanicalReduction>1.0</mechanicalReduction>
        </actuator>
    </transmission>

    <!-- Castor Wheel -->
    <link name="castor_wheel">
        <visual>
            <geometry>
                <sphere radius="0.03"/>
            </geometry>
            <material name="black"/>
        </visual>
        <collision>
            <geometry>
                <sphere radius="0.03"/>
            </geometry>
        </collision>
        <inertial>
            <mass value="0.2"/>
            <inertia ixx="0.001" ixy="0" ixz="0" iyy="0.001" iyz="0" izz="0.001"/>
            <origin xyz="0 0 0" rpy="0 0 0"/>
        </inertial>
    </link>

    <joint name="castor_wheel_joint" type="fixed">
        <parent link="base_link"/>
        <child link="castor_wheel"/>
        <origin xyz="0.17 0 -0.04" rpy="0 0 0"/>
    </joint>

    <!-- Gazebo plugin for ros_control -->
    <gazebo>
        <plugin name="gazebo_ros_control" filename="libgazebo_ros_control.so">
            <robotNamespace>/</robotNamespace>
            <robotSimType>gazebo_ros_control/DefaultRobotHWSim</robotSimType>
        </plugin>
    </gazebo>
</robot>